Workbook

Sheet Project Summary
C1: Employee Bonus Eligibility & Salary Analysis

Sheet Employee_Dataset
A1: Employee ID | B1: Name | C1: Department | D1: Date of Joining | E1: Basic Salary | F1: Location | G1: Bonus% | H1: Bonus Amount | I1: Total Salary | J1: Status | K1: Date | L1: years of Experience | M1: Joining Month Name | N1: High Bonus | O1: Salary Category | P1: Eligibility | Q1: Anniversary Month | R1: Department Code | S1: Employee Summary
A2: EMP001 | B2: Vijay | C2: Marketing | D2: 27/02/2024 | E2: 32671 | F2: Bangalore | G2: {=VLOOKUP(Employee_Dataset!C2:C101,'Bonus Table'!A2:B7,2,FALSE)} -> 0.09 | H2: =E2*G2 -> 2940.39 | I2: =E2+H2 -> 35611.39 | J2: =IF(I2>=25000,"Active","Probation") -> Active | K2: =IFERROR(DATEVALUE(D2),"") -> 45349 | L2: =DATEDIF(K2,TODAY(),"Y") -> 1 | M2: {=TEXT(K2:K101,"mmmm")} -> February | N2: {=IF(H2:H101>5000,"High Bonus","")} | O2: {=IF(I2:I101>=60000,"Top Earner",IF(I2:I101>=40000,"Mid Earner","Low Earner"))} -> Low Earner | P2: =IF(AND(J2="Active",G2>0.1,L2>=3),"Eligible","Not Eligible") -> Not Eligible | Q2: =IF(M2=TEXT(TODAY(),"mmmm"),"Yes","No") -> No | R2: {=LEFT(C2:C101,2)} -> Ma | S2: =_xlfn.TEXTJOIN(",",TRUE,A2,B2,C2,"Salary -"&ROUND(I2,2),J2) -> EMP001,Vijay,Marketing,Salary -35611.39,Active
A3: EMP002 | B3: Dinesh | C3: Finance | D3: 17/02/2024 | E3: 48627 | F3: Bangalore | G3: 0.1 | H3: =E3*G3 -> 4862.7 | I3: =E3+H3 -> 53489.7 | J3: =IF(I3>=25000,"Active","Probation") -> Active | K3: =IFERROR(DATEVALUE(D3),"") -> 45339 | L3: =DATEDIF(K3,TODAY(),"Y") -> 1 | M3: February | O3: Mid Earner | P3: =IF(AND(J3="Active",G3>0.1,L3>=3),"Eligible","Not Eligible") -> Not Eligible | Q3: =IF(M3=TEXT(TODAY(),"mmmm"),"Yes","No") -> No | R3: Fi | S3: =_xlfn.TEXTJOIN(",",TRUE,A3,B3,C3,"Salary -"&ROUND(I3,2),J3) -> EMP002,Dinesh,Finance,Salary -53489.7,Active
A4: EMP003 | B4: Bala | C4: HR | D4: 24/04/2023 | E4: 47891 | F4: Pune | G4: 0.08 | H4: =E4*G4 -> 3831.28 | I4: =E4+H4 -> 51722.28 | J4: =IF(I4>=25000,"Active","Probation") -> Active | K4: =IFERROR(DATEVALUE(D4),"") -> 45040 | L4: =DATEDIF(K4,TODAY(),"Y") -> 2 | M4: April | O4: Mid Earner | P4: =IF(AND(J4="Active",G4>0.1,L4>=3),"Eligible","Not Eligible") -> Not Eligible | Q4: =IF(M4=TEXT(TODAY(),"mmmm"),"Yes","No") -> No | R4: HR | S4: =_xlfn.TEXTJOIN(",",TRUE,A4,B4,C4,"Salary -"&ROUND(I4,2),J4) -> EMP003,Bala,HR,Salary -51722.28,Active
A5: EMP004 | B5: Prakash | C5: Marketing | D5: 23/03/2021 | E5: 43575 | F5: Pune | G5: 0.09 | H5: =E5*G5 -> 3921.75 | I5: =E5+H5 -> 47496.75 | J5: =IF(I5>=25000,"Active","Probation") -> Active | K5: =IFERROR(DATEVALUE(D5),"") -> 44278 | L5: =DATEDIF(K5,TODAY(),"Y") -> 4 | M5: March | O5: Mid Earner | P5: =IF(AND(J5="Active",G5>0.1,L5>=3),"Eligible","Not Eligible") -> Not Eligible | Q5: =IF(M5=TEXT(TODAY(),"mmmm"),"Yes","No") -> No | R5: Ma | S5: =_xlfn.TEXTJOIN(",",TRUE,A5,B5,C5,"Salary -"&ROUND(I5,2),J5) -> EMP004,Prakash,Marketing,Salary -47496.75,Active
A6: EMP005 | B6: Vimal | C6: IT | D6: 23/02/2023 | E6: 32493 | F6: Chennai | G6: 0.12 | H6: =E6*G6 -> 3899.16 | I6: =E6+H6 -> 36392.16 | J6: =IF(I6>=25000,"Active","Probation") -> Active | K6: =IFERROR(DATEVALUE(D6),"") -> 44980 | L6: =DATEDIF(K6,TODAY(),"Y") -> 2 | M6: February | O6: Low Earner | P6: =IF(AND(J6="Active",G6>0.1,L6>=3),"Eligible","Not Eligible") -> Not Eligible | Q6: =IF(M6=TEXT(TODAY(),"mmmm"),"Yes","No") -> No | R6: IT | S6: =_xlfn.TEXTJOIN(",",TRUE,A6,B6,C6,"Salary -"&ROUND(I6,2),J6) -> EMP005,Vimal,IT,Salary -36392.16,Active
A7: EMP006 | B7: Saravanan | C7: Support | D7: 27/03/2021 | E7: 58259 | F7: Pune | G7: 0.07 | H7: =E7*G7 -> 4078.13 | I7: =E7+H7 -> 62337.13 | J7: =IF(I7>=25000,"Active","Probation") -> Active | K7: =IFERROR(DATEVALUE(D7),"") -> 44282 | L7: =DATEDIF(K7,TODAY(),"Y") -> 4 | M7: March | O7: Top Earner | P7: =IF(AND(J7="Active",G7>0.1,L7>=3),"Eligible","Not Eligible") -> Not Eligible | Q7: =IF(M7=TEXT(TODAY(),"mmmm"),"Yes","No") -> No | R7: Su | S7: =_xlfn.TEXTJOIN(",",TRUE,A7,B7,C7,"Salary -"&ROUND(I7,2),J7) -> EMP006,Saravanan,Support,Salary -62337.13,Active
A8: EMP007 | B8: Madhan | C8: HR | D8: 45355 | E8: 36550 | F8: Mumbai | G8: 0.08 | H8: =E8*G8 -> 2924 | I8: =E8+H8 -> 39474 | J8: =IF(I8>=25000,"Active","Probation") -> Active | K8: 45355 | L8: =DATEDIF(K8,TODAY(),"Y") -> 1 | M8: March | O8: Low Earner | P8: =IF(AND(J8="Active",G8>0.1,L8>=3),"Eligible","Not Eligible") -> Not Eligible | Q8: =IF(M8=TEXT(TODAY(),"mmmm"),"Yes","No") -> No | R8: HR | S8: =_xlfn.TEXTJOIN(",",TRUE,A8,B8,C8,"Salary -"&ROUND(I8,2),J8) -> EMP007,Madhan,HR,Salary -39474,Active
A9: EMP008 | B9: Vijay | C9: IT | D9: 23/07/2021 | E9: 46605 | F9: Mumbai | G9: 0.12 | H9: =E9*G9 -> 5592.6 | I9: =E9+H9 -> 52197.6 | J9: =IF(I9>=25000,"Active","Probation") -> Active | K9: =IFERROR(DATEVALUE(D9),"") -> 44400 | L9: =DATEDIF(K9,TODAY(),"Y") -> 4 | M9: July | N9: High Bonus | O9: Mid Earner | P9: =IF(AND(J9="Active",G9>0.1,L9>=3),"Eligible","Not Eligible") -> Eligible | Q9: =IF(M9=TEXT(TODAY(),"mmmm"),"Yes","No") -> No | R9: IT | S9: =_xlfn.TEXTJOIN(",",TRUE,A9,B9,C9,"Salary -"&ROUND(I9,2),J9) -> EMP008,Vijay,IT,Salary -52197.6,Active
A10: EMP009 | B10: Anand | C10: IT | D10: 44050 | E10: 25420 | F10: Mumbai | G10: 0.12 | H10: =E10*G10 -> 3050.4 | I10: =E10+H10 -> 28470.4 | J10: =IF(I10>=25000,"Active","Probation") -> Active | K10: 44050 | L10: =DATEDIF(K10,TODAY(),"Y") -> 5 | M10: August | O10: Low Earner | P10: =IF(AND(J10="Active",G10>0.1,L10>=3),"Eligible","Not Eligible") -> Eligible | Q10: =IF(M10=TEXT(TODAY(),"mmmm"),"Yes","No") -> No | R10: IT | S10: =_xlfn.TEXTJOIN(",",TRUE,A10,B10,C10,"Salary -"&ROUND(I10,2),J10) -> EMP009,Anand,IT,Salary -28470.4,Active
A11: EMP010 | B11: Arjun | C11: Marketing | D11: 21/05/2023 | E11: 58346 | F11: Pune | G11: 0.09 | H11: =E11*G11 -> 5251.14 | I11: =E11+H11 -> 63597.14 | J11: =IF(I11>=25000,"Active","Probation") -> Active | K11: =IFERROR(DATEVALUE(D11),"") -> 45067 | L11: =DATEDIF(K11,TODAY(),"Y") -> 2 | M11: May | N11: High Bonus | O11: Top Earner | P11: =IF(AND(J11="Active",G11>0.1,L11>=3),"Eligible","Not Eligible") -> Not Eligible | Q11: =IF(M11=TEXT(TODAY(),"mmmm"),"Yes","No") -> No | R11: Ma | S11: =_xlfn.TEXTJOIN(",",TRUE,A11,B11,C11,"Salary -"&ROUND(I11,2),J11) -> EMP010,Arjun,Marketing,Salary -63597.14,Active
A12: EMP011 | B12: Karthik | C12: Marketing | D12: 44174 | E12: 41851 | F12: Pune | G12: 0.09 | H12: =E12*G12 -> 3766.59 | I12: =E12+H12 -> 45617.59 | J12: =IF(I12>=25000,"Active","Probation") -> Active | K12: 44174 | L12: =DATEDIF(K12,TODAY(),"Y") -> 5 | M12: December | O12: Mid Earner | P12: =IF(AND(J12="Active",G12>0.1,L12>=3),"Eligible","Not Eligible") -> Not Eligible | Q12: =IF(M12=TEXT(TODAY(),"mmmm"),"Yes","No") -> Yes | R12: Ma | S12: =_xlfn.TEXTJOIN(",",TRUE,A12,B12,C12,"Salary -"&ROUND(I12,2),J12) -> EMP011,Karthik,Marketing,Salary -45617.59,Active
A13: EMP012 | B13: Arjun | C13: Marketing | D13: 25/08/2024 | E13: 52597 | F13: Mumbai | G13: 0.09 | H13: =E13*G13 -> 4733.73 | I13: =E13+H13 -> 57330.73 | J13: =IF(I13>=25000,"Active","Probation") -> Active | K13: =IFERROR(DATEVALUE(D13),"") -> 45529 | L13: =DATEDIF(K13,TODAY(),"Y") -> 1 | M13: August | O13: Mid Earner | P13: =IF(AND(J13="Active",G13>0.1,L13>=3),"Eligible","Not Eligible") -> Not Eligible | Q13: =IF(M13=TEXT(TODAY(),"mmmm"),"Yes","No") -> No | R13: Ma | S13: =_xlfn.TEXTJOIN(",",TRUE,A13,B13,C13,"Salary -"&ROUND(I13,2),J13) -> EMP012,Arjun,Marketing,Salary -57330.73,Active
A14: EMP013 | B14: Surya | C14: IT | D14: 28/01/2021 | E14: 21202 | F14: Pune | G14: 0.12 | H14: =E14*G14 -> 2544.24 | I14: =E14+H14 -> 23746.24 | J14: =IF(I14>=25000,"Active","Probation") -> Probation | K14: =IFERROR(DATEVALUE(D14),"") -> 44224 | L14: =DATEDIF(K14,TODAY(),"Y") -> 4 | M14: January | O14: Low Earner | P14: =IF(AND(J14="Active",G14>0.1,L14>=3),"Eligible","Not Eligible") -> Not Eligible | Q14: =IF(M14=TEXT(TODAY(),"mmmm"),"Yes","No") -> No | R14: IT | S14: =_xlfn.TEXTJOIN(",",TRUE,A14,B14,C14,"Salary -"&ROUND(I14,2),J14) -> EMP013,Surya,IT,Salary -23746.24,Probation
A15: EMP014 | B15: Prakash | C15: Support | D15: 44504 | E15: 44907 | F15: Bangalore | G15: 0.07 | H15: =E15*G15 -> 3143.49 | I15: =E15+H15 -> 48050.49 | J15: =IF(I15>=25000,"Active","Probation") -> Active | K15: 44504 | L15: =DATEDIF(K15,TODAY(),"Y") -> 4 | M15: November | O15: Mid Earner | P15: =IF(AND(J15="Active",G15>0.1,L15>=3),"Eligible","Not Eligible") -> Not Eligible | Q15: =IF(M15=TEXT(TODAY(),"mmmm"),"Yes","No") -> No | R15: Su | S15: =_xlfn.TEXTJOIN(",",TRUE,A15,B15,C15,"Salary -"&ROUND(I15,2),J15) -> EMP014,Prakash,Support,Salary -48050.49,Active
A16: EMP015 | B16: Prakash | C16: Support | D16: 17/02/2022 | E16: 35128 | F16: Chennai | G16: 0.07 | H16: =E16*G16 -> 2458.96 | I16: =E16+H16 -> 37586.96 | J16: =IF(I16>=25000,"Active","Probation") -> Active | K16: =IFERROR(DATEVALUE(D16),"") -> 44609 | L16: =DATEDIF(K16,TODAY(),"Y") -> 3 | M16: February | O16: Low Earner | P16: =IF(AND(J16="Active",G16>0.1,L16>=3),"Eligible","Not Eligible") -> Not Eligible | Q16: =IF(M16=TEXT(TODAY(),"mmmm"),"Yes","No") -> No | R16: Su | S16: =_xlfn.TEXTJOIN(",",TRUE,A16,B16,C16,"Salary -"&ROUND(I16,2),J16) -> EMP015,Prakash,Support,Salary -37586.96,Active
A17: EMP016 | B17: Manoj | C17: HR | D17: 28/01/2022 | E17: 48059 | F17: Delhi | G17: 0.08 | H17: =E17*G17 -> 3844.72 | I17: =E17+H17 -> 51903.72 | J17: =IF(I17>=25000,"Active","Probation") -> Active | K17: =IFERROR(DATEVALUE(D17),"") -> 44589 | L17: =DATEDIF(K17,TODAY(),"Y") -> 3 | M17: January | O17: Mid Earner | P17: =IF(AND(J17="Active",G17>0.1,L17>=3),"Eligible","Not Eligible") -> Not Eligible | Q17: =IF(M17=TEXT(TODAY(),"mmmm"),"Yes","No") -> No | R17: HR | S17: =_xlfn.TEXTJOIN(",",TRUE,A17,B17,C17,"Salary -"&ROUND(I17,2),J17) -> EMP016,Manoj,HR,Salary -51903.72,Active
A18: EMP017 | B18: Madhan | C18: Sales | D18: 45692 | E18: 29422 | F18: Delhi | G18: 0.15 | H18: =E18*G18 -> 4413.3 | I18: =E18+H18 -> 33835.3 | J18: =IF(I18>=25000,"Active","Probation") -> Active | K18: 45692 | L18: =DATEDIF(K18,TODAY(),"Y") -> 0 | M18: February | O18: Low Earner | P18: =IF(AND(J18="Active",G18>0.1,L18>=3),"Eligible","Not Eligible") -> Not Eligible | Q18: =IF(M18=TEXT(TODAY(),"mmmm"),"Yes","No") -> No | R18: Sa | S18: =_xlfn.TEXTJOIN(",",TRUE,A18,B18,C18,"Salary -"&ROUND(I18,2),J18) -> EMP017,Madhan,Sales,Salary -33835.3,Active
A19: EMP018 | B19: Sanjay | C19: IT | D19: 24/07/2023 | E19: 37889 | F19: Bangalore | G19: 0.12 | H19: =E19*G19 -> 4546.68 | I19: =E19+H19 -> 42435.68 | J19: =IF(I19>=25000,"Active","Probation") -> Active | K19: =IFERROR(DATEVALUE(D19),"") -> 45131 | L19: =DATEDIF(K19,TODAY(),"Y") -> 2 | M19: July | O19: Mid Earner | P19: =IF(AND(J19="Active",G19>0.1,L19>=3),"Eligible","Not Eligible") -> Not Eligible | Q19: =IF(M19=TEXT(TODAY(),"mmmm"),"Yes","No") -> No | R19: IT | S19: =_xlfn.TEXTJOIN(",",TRUE,A19,B19,C19,"Salary -"&ROUND(I19,2),J19) -> EMP018,Sanjay,IT,Salary -42435.68,Active
A20: EMP019 | B20: Rajesh | C20: IT | D20: 44659 | E20: 26067 | F20: Bangalore | G20: 0.12 | H20: =E20*G20 -> 3128.04 | I20: =E20+H20 -> 29195.04 | J20: =IF(I20>=25000,"Active","Probation") -> Active | K20: 44659 | L20: =DATEDIF(K20,TODAY(),"Y") -> 3 | M20: April | O20: Low Earner | P20: =IF(AND(J20="Active",G20>0.1,L20>=3),"Eligible","Not Eligible") -> Eligible | Q20: =IF(M20=TEXT(TODAY(),"mmmm"),"Yes","No") -> No | R20: IT | S20: =_xlfn.TEXTJOIN(",",TRUE,A20,B20,C20,"Salary -"&ROUND(I20,2),J20) -> EMP019,Rajesh,IT,Salary -29195.04,Active
A21: EMP020 | B21: Naveen | C21: Support | D21: 44996 | E21: 23418 | F21: Mumbai | G21: 0.07 | H21: =E21*G21 -> 1639.26 | I21: =E21+H21 -> 25057.26 | J21: =IF(I21>=25000,"Active","Probation") -> Active | K21: 44996 | L21: =DATEDIF(K21,TODAY(),"Y") -> 2 | M21: March | O21: Low Earner | P21: =IF(AND(J21="Active",G21>0.1,L21>=3),"Eligible","Not Eligible") -> Not Eligible | Q21: =IF(M21=TEXT(TODAY(),"mmmm"),"Yes","No") -> No | R21: Su | S21: =_xlfn.TEXTJOIN(",",TRUE,A21,B21,C21,"Salary -"&ROUND(I21,2),J21) -> EMP020,Naveen,Support,Salary -25057.26,Active
A22: EMP021 | B22: Karthik | C22: IT | D22: 45450 | E22: 23927 | F22: Mumbai | G22: 0.12 | H22: =E22*G22 -> 2871.24 | I22: =E22+H22 -> 26798.24 | J22: =IF(I22>=25000,"Active","Probation") -> Active | K22: 45450 | L22: =DATEDIF(K22,TODAY(),"Y") -> 1 | M22: June | O22: Low Earner | P22: =IF(AND(J22="Active",G22>0.1,L22>=3),"Eligible","Not Eligible") -> Not Eligible | Q22: =IF(M22=TEXT(TODAY(),"mmmm"),"Yes","No") -> No | R22: IT | S22: =_xlfn.TEXTJOIN(",",TRUE,A22,B22,C22,"Salary -"&ROUND(I22,2),J22) -> EMP021,Karthik,IT,Salary -26798.24,Active
A23: EMP022 | B23: Naveen | C23: Support | D23: 44411 | E23: 64684 | F23: Delhi | G23: 0.07 | H23: =E23*G23 -> 4527.88 | I23: =E23+H23 -> 69211.88 | J23: =IF(I23>=25000,"Active","Probation") -> Active | K23: 44411 | L23: =DATEDIF(K23,TODAY(),"Y") -> 4 | M23: August | O23: Top Earner | P23: =IF(AND(J23="Active",G23>0.1,L23>=3),"Eligible","Not Eligible") -> Not Eligible | Q23: =IF(M23=TEXT(TODAY(),"mmmm"),"Yes","No") -> No | R23: Su | S23: =_xlfn.TEXTJOIN(",",TRUE,A23,B23,C23,"Salary -"&ROUND(I23,2),J23) -> EMP022,Naveen,Support,Salary -69211.88,Active
A24: EMP023 | B24: Ravi | C24: IT | D24: 19/10/2022 | E24: 30753 | F24: Mumbai | G24: 0.12 | H24: =E24*G24 -> 3690.36 | I24: =E24+H24 -> 34443.36 | J24: =IF(I24>=25000,"Active","Probation") -> Active | K24: =IFERROR(DATEVALUE(D24),"") -> 44853 | L24: =DATEDIF(K24,TODAY(),"Y") -> 3 | M24: October | O24: Low Earner | P24: =IF(AND(J24="Active",G24>0.1,L24>=3),"Eligible","Not Eligible") -> Eligible | Q24: =IF(M24=TEXT(TODAY(),"mmmm"),"Yes","No") -> No | R24: IT | S24: =_xlfn.TEXTJOIN(",",TRUE,A24,B24,C24,"Salary -"&ROUND(I24,2),J24) -> EMP023,Ravi,IT,Salary -34443.36,Active
A25: EMP024 | B25: Prakash | C25: Marketing | D25: 26/06/2021 | E25: 30329 | F25: Bangalore | G25: 0.09 | H25: =E25*G25 -> 2729.61 | I25: =E25+H25 -> 33058.61 | J25: =IF(I25>=25000,"Active","Probation") -> Active | K25: =IFERROR(DATEVALUE(D25),"") -> 44373 | L25: =DATEDIF(K25,TODAY(),"Y") -> 4 | M25: June | O25: Low Earner | P25: =IF(AND(J25="Active",G25>0.1,L25>=3),"Eligible","Not Eligible") -> Not Eligible | Q25: =IF(M25=TEXT(TODAY(),"mmmm"),"Yes","No") -> No | R25: Ma | S25: =_xlfn.TEXTJOIN(",",TRUE,A25,B25,C25,"Salary -"&ROUND(I25,2),J25) -> EMP024,Prakash,Marketing,Salary -33058.61,Active
A26: EMP025 | B26: Akash | C26: HR | D26: 22/06/2021 | E26: 29854 | F26: Chennai | G26: 0.08 | H26: =E26*G26 -> 2388.32 | I26: =E26+H26 -> 32242.32 | J26: =IF(I26>=25000,"Active","Probation") -> Active | K26: =IFERROR(DATEVALUE(D26),"") -> 44369 | L26: =DATEDIF(K26,TODAY(),"Y") -> 4 | M26: June | O26: Low Earner | P26: =IF(AND(J26="Active",G26>0.1,L26>=3),"Eligible","Not Eligible") -> Not Eligible | Q26: =IF(M26=TEXT(TODAY(),"mmmm"),"Yes","No") -> No | R26: HR | S26: =_xlfn.TEXTJOIN(",",TRUE,A26,B26,C26,"Salary -"&ROUND(I26,2),J26) -> EMP025,Akash,HR,Salary -32242.32,Active
A27: EMP026 | B27: Bala | C27: Finance | D27: 28/03/2022 | E27: 61900 | F27: Delhi | G27: 0.1 | H27: =E27*G27 -> 6190 | I27: =E27+H27 -> 68090 | J27: =IF(I27>=25000,"Active","Probation") -> Active | K27: =IFERROR(DATEVALUE(D27),"") -> 44648 | L27: =DATEDIF(K27,TODAY(),"Y") -> 3 | M27: March | N27: High Bonus | O27: Top Earner | P27: =IF(AND(J27="Active",G27>0.1,L27>=3),"Eligible","Not Eligible") -> Not Eligible | Q27: =IF(M27=TEXT(TODAY(),"mmmm"),"Yes","No") -> No | R27: Fi | S27: =_xlfn.TEXTJOIN(",",TRUE,A27,B27,C27,"Salary -"&ROUND(I27,2),J27) -> EMP026,Bala,Finance,Salary -68090,Active
A28: EMP027 | B28: Ravi | C28: Finance | D28: 44752 | E28: 57339 | F28: Chennai | G28: 0.1 | H28: =E28*G28 -> 5733.9 | I28: =E28+H28 -> 63072.9 | J28: =IF(I28>=25000,"Active","Probation") -> Active | K28: 44752 | L28: =DATEDIF(K28,TODAY(),"Y") -> 3 | M28: July | N28: High Bonus | O28: Top Earner | P28: =IF(AND(J28="Active",G28>0.1,L28>=3),"Eligible","Not Eligible") -> Not Eligible | Q28: =IF(M28=TEXT(TODAY(),"mmmm"),"Yes","No") -> No | R28: Fi | S28: =_xlfn.TEXTJOIN(",",TRUE,A28,B28,C28,"Salary -"&ROUND(I28,2),J28) -> EMP027,Ravi,Finance,Salary -63072.9,Active
A29: EMP028 | B29: Manoj | C29: Finance | D29: 45176 | E29: 54457 | F29: Bangalore | G29: 0.1 | H29: =E29*G29 -> 5445.7 | I29: =E29+H29 -> 59902.7 | J29: =IF(I29>=25000,"Active","Probation") -> Active | K29: 45176 | L29: =DATEDIF(K29,TODAY(),"Y") -> 2 | M29: September | N29: High Bonus | O29: Mid Earner | P29: =IF(AND(J29="Active",G29>0.1,L29>=3),"Eligible","Not Eligible") -> Not Eligible | Q29: =IF(M29=TEXT(TODAY(),"mmmm"),"Yes","No") -> No | R29: Fi | S29: =_xlfn.TEXTJOIN(",",TRUE,A29,B29,C29,"Salary -"&ROUND(I29,2),J29) -> EMP028,Manoj,Finance,Salary -59902.7,Active
A30: EMP029 | B30: Karthik | C30: Marketing | D30: 44109 | E30: 32832 | F30: Chennai | G30: 0.09 | H30: =E30*G30 -> 2954.88 | I30: =E30+H30 -> 35786.88 | J30: =IF(I30>=25000,"Active","Probation") -> Active | K30: 44109 | L30: =DATEDIF(K30,TODAY(),"Y") -> 5 | M30: October | O30: Low Earner | P30: =IF(AND(J30="Active",G30>0.1,L30>=3),"Eligible","Not Eligible") -> Not Eligible | Q30: =IF(M30=TEXT(TODAY(),"mmmm"),"Yes","No") -> No | R30: Ma | S30: =_xlfn.TEXTJOIN(",",TRUE,A30,B30,C30,"Salary -"&ROUND(I30,2),J30) -> EMP029,Karthik,Marketing,Salary -35786.88,Active
A31: EMP030 | B31: Naveen | C31: HR | D31: 19/12/2022 | E31: 39603 | F31: Mumbai | G31: 0.08 | H31: =E31*G31 -> 3168.24 | I31: =E31+H31 -> 42771.24 | J31: =IF(I31>=25000,"Active","Probation") -> Active | K31: =IFERROR(DATEVALUE(D31),"") -> 44914 | L31: =DATEDIF(K31,TODAY(),"Y") -> 3 | M31: December | O31: Mid Earner | P31: =IF(AND(J31="Active",G31>0.1,L31>=3),"Eligible","Not Eligible") -> Not Eligible | Q31: =IF(M31=TEXT(TODAY(),"mmmm"),"Yes","No") -> Yes | R31: HR | S31: =_xlfn.TEXTJOIN(",",TRUE,A31,B31,C31,"Salary -"&ROUND(I31,2),J31) -> EMP030,Naveen,HR,Salary -42771.24,Active
A32: EMP031 | B32: Surya | C32: Support | D32: 16/01/2024 | E32: 57871 | F32: Delhi | G32: 0.07 | H32: =E32*G32 -> 4050.97 | I32: =E32+H32 -> 61921.97 | J32: =IF(I32>=25000,"Active","Probation") -> Active | K32: =IFERROR(DATEVALUE(D32),"") -> 45307 | L32: =DATEDIF(K32,TODAY(),"Y") -> 1 | M32: January | O32: Top Earner | P32: =IF(AND(J32="Active",G32>0.1,L32>=3),"Eligible","Not Eligible") -> Not Eligible | Q32: =IF(M32=TEXT(TODAY(),"mmmm"),"Yes","No") -> No | R32: Su | S32: =_xlfn.TEXTJOIN(",",TRUE,A32,B32,C32,"Salary -"&ROUND(I32,2),J32) -> EMP031,Surya,Support,Salary -61921.97,Active
A33: EMP032 | B33: Dinesh | C33: Sales | D33: 23/04/2024 | E33: 54439 | F33: Pune | G33: 0.15 | H33: =E33*G33 -> 8165.85 | I33: =E33+H33 -> 62604.85 | J33: =IF(I33>=25000,"Active","Probation") -> Active | K33: =IFERROR(DATEVALUE(D33),"") -> 45405 | L33: =DATEDIF(K33,TODAY(),"Y") -> 1 | M33: April | N33: High Bonus | O33: Top Earner | P33: =IF(AND(J33="Active",G33>0.1,L33>=3),"Eligible","Not Eligible") -> Not Eligible | Q33: =IF(M33=TEXT(TODAY(),"mmmm"),"Yes","No") -> No | R33: Sa | S33: =_xlfn.TEXTJOIN(",",TRUE,A33,B33,C33,"Salary -"&ROUND(I33,2),J33) -> EMP032,Dinesh,Sales,Salary -62604.85,Active
A34: EMP033 | B34: Karthik | C34: Marketing | D34: 44810 | E34: 51012 | F34: Mumbai | G34: 0.09 | H34: =E34*G34 -> 4591.08 | I34: =E34+H34 -> 55603.08 | J34: =IF(I34>=25000,"Active","Probation") -> Active | K34: 44810 | L34: =DATEDIF(K34,TODAY(),"Y") -> 3 | M34: September | O34: Mid Earner | P34: =IF(AND(J34="Active",G34>0.1,L34>=3),"Eligible","Not Eligible") -> Not Eligible | Q34: =IF(M34=TEXT(TODAY(),"mmmm"),"Yes","No") -> No | R34: Ma | S34: =_xlfn.TEXTJOIN(",",TRUE,A34,B34,C34,"Salary -"&ROUND(I34,2),J34) -> EMP033,Karthik,Marketing,Salary -55603.08,Active
A35: EMP034 | B35: Gokul | C35: Finance | D35: 28/11/2024 | E35: 55827 | F35: Bangalore | G35: 0.1 | H35: =E35*G35 -> 5582.7 | I35: =E35+H35 -> 61409.7 | J35: =IF(I35>=25000,"Active","Probation") -> Active | K35: =IFERROR(DATEVALUE(D35),"") -> 45624 | L35: =DATEDIF(K35,TODAY(),"Y") -> 1 | M35: November | N35: High Bonus | O35: Top Earner | P35: =IF(AND(J35="Active",G35>0.1,L35>=3),"Eligible","Not Eligible") -> Not Eligible | Q35: =IF(M35=TEXT(TODAY(),"mmmm"),"Yes","No") -> No | R35: Fi | S35: =_xlfn.TEXTJOIN(",",TRUE,A35,B35,C35,"Salary -"&ROUND(I35,2),J35) -> EMP034,Gokul,Finance,Salary -61409.7,Active
A36: EMP035 | B36: Surya | C36: Marketing | D36: 44692 | E36: 60685 | F36: Pune | G36: 0.09 | H36: =E36*G36 -> 5461.65 | I36: =E36+H36 -> 66146.65 | J36: =IF(I36>=25000,"Active","Probation") -> Active | K36: 44692 | L36: =DATEDIF(K36,TODAY(),"Y") -> 3 | M36: May | N36: High Bonus | O36: Top Earner | P36: =IF(AND(J36="Active",G36>0.1,L36>=3),"Eligible","Not Eligible") -> Not Eligible | Q36: =IF(M36=TEXT(TODAY(),"mmmm"),"Yes","No") -> No | R36: Ma | S36: =_xlfn.TEXTJOIN(",",TRUE,A36,B36,C36,"Salary -"&ROUND(I36,2),J36) -> EMP035,Surya,Marketing,Salary -66146.65,Active
A37: EMP036 | B37: Madhan | C37: Marketing | D37: 44692 | E37: 57917 | F37: Pune | G37: 0.09 | H37: =E37*G37 -> 5212.53 | I37: =E37+H37 -> 63129.53 | J37: =IF(I37>=25000,"Active","Probation") -> Active | K37: 44692 | L37: =DATEDIF(K37,TODAY(),"Y") -> 3 | M37: May | N37: High Bonus | O37: Top Earner | P37: =IF(AND(J37="Active",G37>0.1,L37>=3),"Eligible","Not Eligible") -> Not Eligible | Q37: =IF(M37=TEXT(TODAY(),"mmmm"),"Yes","No") -> No | R37: Ma | S37: =_xlfn.TEXTJOIN(",",TRUE,A37,B37,C37,"Salary -"&ROUND(I37,2),J37) -> EMP036,Madhan,Marketing,Salary -63129.53,Active
A38: EMP037 | B38: Naveen | C38: Sales | D38: 45569 | E38: 40563 | F38: Chennai | G38: 0.15 | H38: =E38*G38 -> 6084.45 | I38: =E38+H38 -> 46647.45 | J38: =IF(I38>=25000,"Active","Probation") -> Active | K38: 45569 | L38: =DATEDIF(K38,TODAY(),"Y") -> 1 | M38: October | N38: High Bonus | O38: Mid Earner | P38: =IF(AND(J38="Active",G38>0.1,L38>=3),"Eligible","Not Eligible") -> Not Eligible | Q38: =IF(M38=TEXT(TODAY(),"mmmm"),"Yes","No") -> No | R38: Sa | S38: =_xlfn.TEXTJOIN(",",TRUE,A38,B38,C38,"Salary -"&ROUND(I38,2),J38) -> EMP037,Naveen,Sales,Salary -46647.45,Active
A39: EMP038 | B39: Ramesh | C39: Finance | D39: 45235 | E39: 55771 | F39: Delhi | G39: 0.1 | H39: =E39*G39 -> 5577.1 | I39: =E39+H39 -> 61348.1 | J39: =IF(I39>=25000,"Active","Probation") -> Active | K39: 45235 | L39: =DATEDIF(K39,TODAY(),"Y") -> 2 | M39: November | N39: High Bonus | O39: Top Earner | P39: =IF(AND(J39="Active",G39>0.1,L39>=3),"Eligible","Not Eligible") -> Not Eligible | Q39: =IF(M39=TEXT(TODAY(),"mmmm"),"Yes","No") -> No | R39: Fi | S39: =_xlfn.TEXTJOIN(",",TRUE,A39,B39,C39,"Salary -"&ROUND(I39,2),J39) -> EMP038,Ramesh,Finance,Salary -61348.1,Active
A40: EMP039 | B40: Sanjay | C40: Marketing | D40: 17/03/2025 | E40: 35202 | F40: Bangalore | G40: 0.09 | H40: =E40*G40 -> 3168.18 | I40: =E40+H40 -> 38370.18 | J40: =IF(I40>=25000,"Active","Probation") -> Active | K40: =IFERROR(DATEVALUE(D40),"") -> 45733 | L40: =DATEDIF(K40,TODAY(),"Y") -> 0 | M40: March | O40: Low Earner | P40: =IF(AND(J40="Active",G40>0.1,L40>=3),"Eligible","Not Eligible") -> Not Eligible | Q40: =IF(M40=TEXT(TODAY(),"mmmm"),"Yes","No") -> No | R40: Ma | S40: =_xlfn.TEXTJOIN(",",TRUE,A40,B40,C40,"Salary -"&ROUND(I40,2),J40) -> EMP039,Sanjay,Marketing,Salary -38370.18,Active
...

Sheet Bonus Table
A1: Department | B1: Bonus %
A2: Finance | B2: 0.1
A3: HR | B3: 0.08
A4: IT | B4: 0.12
A5: Sales | B5: 0.15
A6: Marketing | B6: 0.09
A7: Support | B7: 0.07

Sheet Summary Count
B2: Employee Report - Dataset Summary Counts
B3: Total employees🧑‍🤝‍🧑 | D3: 100
B4: Active employees✅ | D4: =COUNTIF(Employee_Dataset!J2:J101,"Active") -> 93 | I4: Salary Category Summary📊:
B5: Probation Employee ❎ | D5: =COUNTIF(Employee_Dataset!J2:J101,"Probation") -> 7 | I5: 1. High Salary | K5: 31
B6: Employee eligible for bonus 💰 | D6: =COUNTIF(Employee_Dataset!P2:P101,"Eligible") -> 13 | I6: 2. Medium Salary | K6: =COUNTIF(Employee_Dataset!O2:O101,"Mid Earner") -> 32
B7: Highest Salary in the Dataset 📈 | D7: =MAX(Employee_Dataset!I2:I101) -> 73348.15 | I7: 3. Low Salary | K7: =COUNTIF(Employee_Dataset!O2:O101,"Low Earner") -> 37
B8: Lowest Salary in the Dataset 📉 | D8: =MIN(Employee_Dataset!I2:I101) -> 20402.28
B9: Department with the highest number of employees🏢 | D9: Marketing-24
B10: Total number of employees with High-Bonus Eligibility 🎯 | D10: 10

Sheet Pivot Sheet
A1: Department | B1: Count of Employee ID
A2: Marketing | B2: 24
A3: Support | B3: 18
A4: IT | B4: 17
A5: HR | B5: 16
A6: Sales | B6: 14
A7: Finance | B7: 11
A8: Grand Total | B8: 100
